<?xml version="1.0" encoding="utf-8"?>
<robot name="go2_x5">
  <!-- GO2 Dog Robot -->
  <link name="base">
    <inertial>
      <origin xyz="0.021112 0 -0.005366" rpy="0 0 0" />
      <mass value="6.921" />
      <inertia ixx="0.02448" ixy="0.00012166" ixz="0.0014849" iyy="0.098077" iyz="-3.12E-05" izz="0.107" />
    </inertial>
    <visual>
      <origin xyz="0 0 0" rpy="0 0 0" />
      <geometry>
        <mesh filename="./meshes/base.dae" />
      </geometry>
      <material name="深色橡胶_001-effect"><color rgba="0.6717055 0.6924257 0.7742702 1" /></material><material name="白色logo_001-effect"><color rgba="1 1 1 1" /></material><material name="黑色贴纸_007-effect"><color rgba="0.009018 0.009018 0.009018 1" /></material><material name="黑色金属_007-effect"><color rgba="0.01341 0.01341 0.01341 1" /></material><material name="黑色塑料_003-effect"><color rgba="0.023455 0.023455 0.023455 1" /></material></visual>
    <collision>
      <origin rpy="0 0 0" xyz="0 0 0" />
      <geometry>
        <box size="0.3762 0.0935 0.114" />
      </geometry>
    </collision>
  </link>
  <link name="Head_upper">
    <inertial>
      <origin xyz="0 0 0" rpy="0 0 0" />
      <mass value="0.001" />
      <inertia ixx="9.6e-06" ixy="0" ixz="0" iyy="9.6e-06" iyz="0" izz="9.6e-06" />
    </inertial>
    <collision>
      <origin xyz="0 0 0" rpy="0 0 0" />
      <geometry>
        <cylinder radius="0.05" length="0.09" />
      </geometry>
    </collision>
  </link>
  <joint name="Head_upper_joint" type="fixed" dont_collapse="true">
    <origin xyz="0.285 0 0.01" rpy="0 0 0" />
    <parent link="base" />
    <child link="Head_upper" />
    <axis xyz="0 0 0" />
  </joint>
  <link name="Head_lower">
    <inertial>
      <origin xyz="0 0 0" rpy="0 0 0" />
      <mass value="0.001" />
      <inertia ixx="9.6e-06" ixy="0" ixz="0" iyy="9.6e-06" iyz="0" izz="9.6e-06" />
    </inertial>
    <collision>
      <origin xyz="0 0 0" rpy="0 0 0" />
      <geometry>
        <sphere radius="0.047" />
      </geometry>
    </collision>
  </link>
  <joint name="Head_lower_joint" type="fixed" dont_collapse="true">
    <origin xyz="0.008 0 -0.07" rpy="0 0 0" />
    <parent link="Head_upper" />
    <child link="Head_lower" />
    <axis xyz="0 0 0" />
  </joint>
  <link name="FL_hip">
    <inertial>
      <origin xyz="-0.0054 0.00194 -0.000105" rpy="0 0 0" />
      <mass value="0.678" />
      <inertia ixx="0.00048" ixy="-3.01E-06" ixz="1.11E-06" iyy="0.000884" iyz="-1.42E-06" izz="0.000596" />
    </inertial>
    <visual>
      <origin xyz="0 0 0" rpy="0 0 0" />
      <geometry>
        <mesh filename="./meshes/hip.dae" />
      </geometry>
      <material name="深色橡胶_001-effect"><color rgba="0.6717055 0.6924257 0.7742702 1" /></material><material name="Material-effect"><color rgba="0.9 0.95 0.95 1" /></material></visual>
    <collision>
      <origin rpy="1.5707963267948966 0 0" xyz="0 0.08 0" />
      <geometry>
        <cylinder length="0.04" radius="0.046" />
      </geometry>
    </collision>
  </link>
  <joint name="FL_hip_joint" type="revolute">
    <origin xyz="0.1934 0.0465 0" rpy="0 0 0" />
    <parent link="base" />
    <child link="FL_hip" />
    <axis xyz="1 0 0" />
    <limit lower="-1.0472" upper="1.0472" effort="23.7" velocity="30.1" />
  </joint>
  <link name="FL_hip_rotor">
    <inertial>
      <origin rpy="0 0 0" xyz="0.0 0.0 0.0" />
      <mass value="0.089" />
      <inertia ixx="0.000111842" ixy="0.0" ixz="0.0" iyy="0.000059647" iyz="0.0" izz="0.000059647" />
    </inertial>
  </link>
  <joint name="FL_hip_rotor_joint" type="fixed">
    <origin rpy="0 0 0" xyz="0.11215 0.04675 0" />
    <parent link="base" />
    <child link="FL_hip_rotor" />
  </joint>
  <link name="FL_thigh">
    <inertial>
      <origin xyz="-0.00374 -0.0223 -0.0327" rpy="0 0 0" />
      <mass value="1.152" />
      <inertia ixx="0.00584" ixy="8.72E-05" ixz="-0.000289" iyy="0.0058" iyz="0.000808" izz="0.00103" />
    </inertial>
    <visual>
      <origin xyz="0 0 0" rpy="0 0 0" />
      <geometry>
        <mesh filename="./meshes/thigh.dae" />
      </geometry>
      <material name="深色橡胶_003-effect"><color rgba="0.6717055 0.6924257 0.7742702 1" /></material><material name="Material_009-effect"><color rgba="0.9 0.95 0.95 1" /></material></visual>
    <collision>
      <origin rpy="0 1.5707963267948966 0" xyz="0 0 -0.1065" />
      <geometry>
        <box size="0.213 0.0245 0.034" />
      </geometry>
    </collision>
  </link>
  <joint name="FL_thigh_joint" type="revolute">
    <origin xyz="0 0.0955 0" rpy="0 0 0" />
    <parent link="FL_hip" />
    <child link="FL_thigh" />
    <axis xyz="0 1 0" />
    <limit lower="-1.5708" upper="3.4907" effort="23.7" velocity="30.1" />
  </joint>
  <link name="FL_thigh_rotor">
    <inertial>
      <origin rpy="0 0 0" xyz="0.0 0.0 0.0" />
      <mass value="0.089" />
      <inertia ixx="0.000059647" ixy="0.0" ixz="0.0" iyy="0.000111842" iyz="0.0" izz="0.000059647" />
    </inertial>
  </link>
  <joint name="FL_thigh_rotor_joint" type="fixed">
    <origin rpy="0 0 0" xyz="0 -0.00015 0" />
    <parent link="FL_hip" />
    <child link="FL_thigh_rotor" />
  </joint>
  <link name="FL_calf">
    <inertial>
      <origin xyz="0.00548 -0.000975 -0.115" rpy="0 0 0" />
      <mass value="0.154" />
      <inertia ixx="0.00108" ixy="3.4E-07" ixz="1.72E-05" iyy="0.0011" iyz="8.28E-06" izz="3.29E-05" />
    </inertial>
    <visual>
      <origin xyz="0 0 0" rpy="0 0 0" />
      <geometry>
        <mesh filename="./meshes/calf.dae" />
      </geometry>
      <material name="黑色足端_005-effect"><color rgba="0 0 0 1" /></material><material name="深色橡胶_005-effect"><color rgba="0.6717055 0.6924257 0.7742702 1" /></material></visual>
    <collision>
      <origin rpy="0 -0.21 0" xyz="0.008 0 -0.06" />
      <geometry>
        <cylinder length="0.12" radius="0.012" />
      </geometry>
    </collision>
  </link>
  <joint name="FL_calf_joint" type="revolute">
    <origin xyz="0 0 -0.213" rpy="0 0 0" />
    <parent link="FL_thigh" />
    <child link="FL_calf" />
    <axis xyz="0 1 0" />
    <limit lower="-2.7227" upper="-0.83776" effort="45.43" velocity="15.70" />
  </joint>
  <link name="FL_calflower">
    <collision>
      <origin rpy="0 0 0" xyz="0 0 0" />
      <geometry>
        <cylinder length="0.065" radius="0.011" />
      </geometry>
    </collision>
  </link>
  <joint name="FL_calflower_joint" type="fixed">
    <origin xyz="0.020 0 -0.148" rpy="0 0.05 0" />
    <parent link="FL_calf" />
    <child link="FL_calflower" />
    <axis xyz="0 0 0" />
  </joint>
  <link name="FL_calflower1">
    <collision>
      <origin rpy="0 0 0" xyz="0 0 0" />
      <geometry>
        <cylinder length="0.03" radius="0.0155" />
      </geometry>
    </collision>
  </link>
  <joint name="FL_calflower1_joint" type="fixed">
    <origin xyz="-0.01 0 -0.04" rpy="0 0.48 0" />
    <parent link="FL_calflower" />
    <child link="FL_calflower1" />
    <axis xyz="0 0 0" />
  </joint>
  <link name="FL_calf_rotor">
    <inertial>
      <origin rpy="0 0 0" xyz="0.0 0.0 0.0" />
      <mass value="0.089" />
      <inertia ixx="0.000059647" ixy="0.0" ixz="0.0" iyy="0.000111842" iyz="0.0" izz="0.000059647" />
    </inertial>
  </link>
  <joint name="FL_calf_rotor_joint" type="fixed">
    <origin rpy="0 0 0" xyz="0 -0.03235 0" />
    <parent link="FL_thigh" />
    <child link="FL_calf_rotor" />
  </joint>
  <link name="FL_foot">
    <inertial>
      <origin xyz="0 0 0" rpy="0 0 0" />
      <mass value="0.04" />
      <inertia ixx="9.6e-06" ixy="0" ixz="0" iyy="9.6e-06" iyz="0" izz="9.6e-06" />
    </inertial>
    <visual>
      <origin xyz="0 0 0" rpy="0 0 0" />
      <geometry>
        <mesh filename="./meshes/foot.dae" />
      </geometry>
      <material name="黑色足端_007-effect"><color rgba="0 0 0 1" /></material></visual>
    <collision>
      <origin rpy="0 0 0" xyz="-0.002 0 0" />
      <geometry>
        <sphere radius="0.022" />
      </geometry>
    </collision>
  </link>
  <joint name="FL_foot_joint" type="fixed" dont_collapse="true">
    <origin xyz="0 0 -0.213" rpy="0 0 0" />
    <parent link="FL_calf" />
    <child link="FL_foot" />
    <axis xyz="0 0 0" />
  </joint>
  <link name="FR_hip">
    <inertial>
      <origin xyz="-0.0054 -0.00194 -0.000105" rpy="0 0 0" />
      <mass value="0.678" />
      <inertia ixx="0.00048" ixy="3.01E-06" ixz="1.11E-06" iyy="0.000884" iyz="1.42E-06" izz="0.000596" />
    </inertial>
    <visual>
      <origin xyz="0 0 0" rpy="3.1415 0 0" />
      <geometry>
        <mesh filename="./meshes/hip.dae" />
      </geometry>
      <material name="深色橡胶_001-effect"><color rgba="0.6717055 0.6924257 0.7742702 1" /></material><material name="Material-effect"><color rgba="0.9 0.95 0.95 1" /></material></visual>
    <collision>
      <origin rpy="1.5707963267948966 0 0" xyz="0 -0.08 0" />
      <geometry>
        <cylinder length="0.04" radius="0.046" />
      </geometry>
    </collision>
  </link>
  <joint name="FR_hip_joint" type="revolute">
    <origin xyz="0.1934 -0.0465 0" rpy="0 0 0" />
    <parent link="base" />
    <child link="FR_hip" />
    <axis xyz="1 0 0" />
    <limit lower="-1.0472" upper="1.0472" effort="23.7" velocity="30.1" />
  </joint>
  <link name="FR_hip_rotor">
    <inertial>
      <origin rpy="0 0 0" xyz="0.0 0.0 0.0" />
      <mass value="0.089" />
      <inertia ixx="0.000111842" ixy="0.0" ixz="0.0" iyy="0.000059647" iyz="0.0" izz="0.000059647" />
    </inertial>
  </link>
  <joint name="FR_hip_rotor_joint" type="fixed">
    <origin rpy="0 0 0" xyz="0.11215 -0.04675 0" />
    <parent link="base" />
    <child link="FR_hip_rotor" />
  </joint>
  <link name="FR_thigh">
    <inertial>
      <origin xyz="-0.00374 0.0223 -0.0327" rpy="0 0 0" />
      <mass value="1.152" />
      <inertia ixx="0.00584" ixy="-8.72E-05" ixz="-0.000289" iyy="0.0058" iyz="-0.000808" izz="0.00103" />
    </inertial>
    <visual>
      <origin xyz="0 0 0" rpy="0 0 0" />
      <geometry>
        <mesh filename="./meshes/thigh_mirror.dae" />
      </geometry>
      <material name="深色橡胶_012-effect"><color rgba="0.6717055 0.6924257 0.7742702 1" /></material><material name="Material_011-effect"><color rgba="0.9 0.95 0.95 1" /></material></visual>
    <collision>
      <origin rpy="0 1.5707963267948966 0" xyz="0 0 -0.1065" />
      <geometry>
        <box size="0.213 0.0245 0.034" />
      </geometry>
    </collision>
  </link>
  <joint name="FR_thigh_joint" type="revolute">
    <origin xyz="0 -0.0955 0" rpy="0 0 0" />
    <parent link="FR_hip" />
    <child link="FR_thigh" />
    <axis xyz="0 1 0" />
    <limit lower="-1.5708" upper="3.4907" effort="23.7" velocity="30.1" />
  </joint>
  <link name="FR_thigh_rotor">
    <inertial>
      <origin rpy="0 0 0" xyz="0.0 0.0 0.0" />
      <mass value="0.089" />
      <inertia ixx="0.000059647" ixy="0.0" ixz="0.0" iyy="0.000111842" iyz="0.0" izz="0.000059647" />
    </inertial>
  </link>
  <joint name="FR_thigh_rotor_joint" type="fixed">
    <origin rpy="0 0 0" xyz="0 0.00015 0" />
    <parent link="FR_hip" />
    <child link="FR_thigh_rotor" />
  </joint>
  <link name="FR_calf">
    <inertial>
      <origin xyz="0.00548 0.000975 -0.115" rpy="0 0 0" />
      <mass value="0.154" />
      <inertia ixx="0.00108" ixy="-3.4E-07" ixz="1.72E-05" iyy="0.0011" iyz="-8.28E-06" izz="3.29E-05" />
    </inertial>
    <visual>
      <origin xyz="0 0 0" rpy="0 0 0" />
      <geometry>
        <mesh filename="./meshes/calf_mirror.dae" />
      </geometry>
      <material name="黑色足端_006-effect"><color rgba="0 0 0 1" /></material><material name="深色橡胶_007-effect"><color rgba="0.6717055 0.6924257 0.7742702 1" /></material></visual>
    <collision>
      <origin rpy="0 -0.2 0" xyz="0.01 0 -0.06" />
      <geometry>
        <cylinder length="0.12" radius="0.013" />
      </geometry>
    </collision>
  </link>
  <joint name="FR_calf_joint" type="revolute">
    <origin xyz="0 0 -0.213" rpy="0 0 0" />
    <parent link="FR_thigh" />
    <child link="FR_calf" />
    <axis xyz="0 1 0" />
    <limit lower="-2.7227" upper="-0.83776" effort="45.43" velocity="15.70" />
  </joint>
  <link name="FR_calflower">
    <collision>
      <origin rpy="0 0 0" xyz="0 0 0" />
      <geometry>
        <cylinder length="0.065" radius="0.011" />
      </geometry>
    </collision>
  </link>
  <joint name="FR_calflower_joint" type="fixed">
    <origin xyz="0.020 0 -0.148" rpy="0 0.05 0" />
    <parent link="FR_calf" />
    <child link="FR_calflower" />
    <axis xyz="0 0 0" />
  </joint>
  <link name="FR_calflower1">
    <collision>
      <origin rpy="0 0 0" xyz="0 0 0" />
      <geometry>
        <cylinder length="0.03" radius="0.0155" />
      </geometry>
    </collision>
  </link>
  <joint name="FR_calflower1_joint" type="fixed">
    <origin xyz="-0.01 0 -0.04" rpy="0 0.48 0" />
    <parent link="FR_calflower" />
    <child link="FR_calflower1" />
    <axis xyz="0 0 0" />
  </joint>
  <link name="FR_calf_rotor">
    <inertial>
      <origin rpy="0 0 0" xyz="0.0 0.0 0.0" />
      <mass value="0.089" />
      <inertia ixx="0.000059647" ixy="0.0" ixz="0.0" iyy="0.000111842" iyz="0.0" izz="0.000059647" />
    </inertial>
  </link>
  <joint name="FR_calf_rotor_joint" type="fixed">
    <origin rpy="0 0 0" xyz="0 0.03235 0" />
    <parent link="FR_thigh" />
    <child link="FR_calf_rotor" />
  </joint>
  <link name="FR_foot">
    <inertial>
      <origin xyz="0 0 0" rpy="0 0 0" />
      <mass value="0.04" />
      <inertia ixx="9.6e-06" ixy="0" ixz="0" iyy="9.6e-06" iyz="0" izz="9.6e-06" />
    </inertial>
    <visual>
      <origin xyz="0 0 0" rpy="0 0 0" />
      <geometry>
        <mesh filename="./meshes/foot.dae" />
      </geometry>
      <material name="黑色足端_007-effect"><color rgba="0 0 0 1" /></material></visual>
    <collision>
      <origin rpy="0 0 0" xyz="-0.002 0 0" />
      <geometry>
        <sphere radius="0.022" />
      </geometry>
    </collision>
  </link>
  <joint name="FR_foot_joint" type="fixed" dont_collapse="true">
    <origin xyz="0 0 -0.213" rpy="0 0 0" />
    <parent link="FR_calf" />
    <child link="FR_foot" />
    <axis xyz="0 0 0" />
  </joint>
  <link name="RL_hip">
    <inertial>
      <origin xyz="0.0054 0.00194 -0.000105" rpy="0 0 0" />
      <mass value="0.678" />
      <inertia ixx="0.00048" ixy="3.01E-06" ixz="-1.11E-06" iyy="0.000884" iyz="-1.42E-06" izz="0.000596" />
    </inertial>
    <visual>
      <origin xyz="0 0 0" rpy="0 3.1415 0" />
      <geometry>
        <mesh filename="./meshes/hip.dae" />
      </geometry>
      <material name="深色橡胶_001-effect"><color rgba="0.6717055 0.6924257 0.7742702 1" /></material><material name="Material-effect"><color rgba="0.9 0.95 0.95 1" /></material></visual>
    <collision>
      <origin rpy="1.5707963267948966 0 0" xyz="0 0.08 0" />
      <geometry>
        <cylinder length="0.04" radius="0.046" />
      </geometry>
    </collision>
  </link>
  <joint name="RL_hip_joint" type="revolute">
    <origin xyz="-0.1934 0.0465 0" rpy="0 0 0" />
    <parent link="base" />
    <child link="RL_hip" />
    <axis xyz="1 0 0" />
    <limit lower="-1.0472" upper="1.0472" effort="23.7" velocity="30.1" />
  </joint>
  <link name="RL_hip_rotor">
    <inertial>
      <origin rpy="0 0 0" xyz="0.0 0.0 0.0" />
      <mass value="0.089" />
      <inertia ixx="0.000111842" ixy="0.0" ixz="0.0" iyy="0.000059647" iyz="0.0" izz="0.000059647" />
    </inertial>
  </link>
  <joint name="RL_hip_rotor_joint" type="fixed">
    <origin rpy="0 0 0" xyz="-0.11215 0.04675 0" />
    <parent link="base" />
    <child link="RL_hip_rotor" />
  </joint>
  <link name="RL_thigh">
    <inertial>
      <origin xyz="-0.00374 -0.0223 -0.0327" rpy="0 0 0" />
      <mass value="1.152" />
      <inertia ixx="0.00584" ixy="8.72E-05" ixz="-0.000289" iyy="0.0058" iyz="0.000808" izz="0.00103" />
    </inertial>
    <visual>
      <origin xyz="0 0 0" rpy="0 0 0" />
      <geometry>
        <mesh filename="./meshes/thigh.dae" />
      </geometry>
      <material name="深色橡胶_003-effect"><color rgba="0.6717055 0.6924257 0.7742702 1" /></material><material name="Material_009-effect"><color rgba="0.9 0.95 0.95 1" /></material></visual>
    <collision>
      <origin rpy="0 1.5707963267948966 0" xyz="0 0 -0.1065" />
      <geometry>
        <box size="0.213 0.0245 0.034" />
      </geometry>
    </collision>
  </link>
  <joint name="RL_thigh_joint" type="revolute">
    <origin xyz="0 0.0955 0" rpy="0 0 0" />
    <parent link="RL_hip" />
    <child link="RL_thigh" />
    <axis xyz="0 1 0" />
    <limit lower="-0.5236" upper="4.5379" effort="23.7" velocity="30.1" />
  </joint>
  <link name="RL_thigh_rotor">
    <inertial>
      <origin rpy="0 0 0" xyz="0.0 0.0 0.0" />
      <mass value="0.089" />
      <inertia ixx="0.000059647" ixy="0.0" ixz="0.0" iyy="0.000111842" iyz="0.0" izz="0.000059647" />
    </inertial>
  </link>
  <joint name="RL_thigh_rotor_joint" type="fixed">
    <origin rpy="0 0 0" xyz="0 -0.00015 0" />
    <parent link="RL_hip" />
    <child link="RL_thigh_rotor" />
  </joint>
  <link name="RL_calf">
    <inertial>
      <origin xyz="0.00548 -0.000975 -0.115" rpy="0 0 0" />
      <mass value="0.154" />
      <inertia ixx="0.00108" ixy="3.4E-07" ixz="1.72E-05" iyy="0.0011" iyz="8.28E-06" izz="3.29E-05" />
    </inertial>
    <visual>
      <origin xyz="0 0 0" rpy="0 0 0" />
      <geometry>
        <mesh filename="./meshes/calf.dae" />
      </geometry>
      <material name="黑色足端_005-effect"><color rgba="0 0 0 1" /></material><material name="深色橡胶_005-effect"><color rgba="0.6717055 0.6924257 0.7742702 1" /></material></visual>
    <collision>
      <origin rpy="0 -0.2 0" xyz="0.01 0 -0.06" />
      <geometry>
        <cylinder length="0.12" radius="0.013" />
      </geometry>
    </collision>
  </link>
  <joint name="RL_calf_joint" type="revolute">
    <origin xyz="0 0 -0.213" rpy="0 0 0" />
    <parent link="RL_thigh" />
    <child link="RL_calf" />
    <axis xyz="0 1 0" />
    <limit lower="-2.7227" upper="-0.83776" effort="45.43" velocity="15.70" />
  </joint>
  <link name="RL_calflower">
    <collision>
      <origin rpy="0 0 0" xyz="0 0 0" />
      <geometry>
        <cylinder length="0.065" radius="0.011" />
      </geometry>
    </collision>
  </link>
  <joint name="RL_calflower_joint" type="fixed">
    <origin xyz="0.020 0 -0.148" rpy="0 0.05 0" />
    <parent link="RL_calf" />
    <child link="RL_calflower" />
    <axis xyz="0 0 0" />
  </joint>
  <link name="RL_calflower1">
    <collision>
      <origin rpy="0 0 0" xyz="0 0 0" />
      <geometry>
        <cylinder length="0.03" radius="0.0155" />
      </geometry>
    </collision>
  </link>
  <joint name="RL_calflower1_joint" type="fixed">
    <origin xyz="-0.01 0 -0.04" rpy="0 0.48 0" />
    <parent link="RL_calflower" />
    <child link="RL_calflower1" />
    <axis xyz="0 0 0" />
  </joint>
  <link name="RL_calf_rotor">
    <inertial>
      <origin rpy="0 0 0" xyz="0.0 0.0 0.0" />
      <mass value="0.089" />
      <inertia ixx="0.000059647" ixy="0.0" ixz="0.0" iyy="0.000111842" iyz="0.0" izz="0.000059647" />
    </inertial>
  </link>
  <joint name="RL_calf_rotor_joint" type="fixed">
    <origin rpy="0 0 0" xyz="0 -0.03235 0" />
    <parent link="RL_thigh" />
    <child link="RL_calf_rotor" />
  </joint>
  <link name="RL_foot">
    <inertial>
      <origin xyz="0 0 0" rpy="0 0 0" />
      <mass value="0.04" />
      <inertia ixx="9.6e-06" ixy="0" ixz="0" iyy="9.6e-06" iyz="0" izz="9.6e-06" />
    </inertial>
    <visual>
      <origin xyz="0 0 0" rpy="0 0 0" />
      <geometry>
        <mesh filename="./meshes/foot.dae" />
      </geometry>
      <material name="黑色足端_007-effect"><color rgba="0 0 0 1" /></material></visual>
    <collision>
      <origin rpy="0 0 0" xyz="-0.002 0 0" />
      <geometry>
        <sphere radius="0.022" />
      </geometry>
    </collision>
  </link>
  <joint name="RL_foot_joint" type="fixed" dont_collapse="true">
    <origin xyz="0 0 -0.213" rpy="0 0 0" />
    <parent link="RL_calf" />
    <child link="RL_foot" />
    <axis xyz="0 0 0" />
  </joint>
  <link name="RR_hip">
    <inertial>
      <origin xyz="0.0054 -0.00194 -0.000105" rpy="0 0 0" />
      <mass value="0.678" />
      <inertia ixx="0.00048" ixy="-3.01E-06" ixz="-1.11E-06" iyy="0.000884" iyz="1.42E-06" izz="0.000596" />
    </inertial>
    <visual>
      <origin xyz="0 0 0" rpy="3.1415 3.1415 0" />
      <geometry>
        <mesh filename="./meshes/hip.dae" />
      </geometry>
      <material name="深色橡胶_001-effect"><color rgba="0.6717055 0.6924257 0.7742702 1" /></material><material name="Material-effect"><color rgba="0.9 0.95 0.95 1" /></material></visual>
    <collision>
      <origin rpy="1.5707963267948966 0 0" xyz="0 -0.08 0" />
      <geometry>
        <cylinder length="0.04" radius="0.046" />
      </geometry>
    </collision>
  </link>
  <joint name="RR_hip_joint" type="revolute">
    <origin xyz="-0.1934 -0.0465 0" rpy="0 0 0" />
    <parent link="base" />
    <child link="RR_hip" />
    <axis xyz="1 0 0" />
    <limit lower="-1.0472" upper="1.0472" effort="23.7" velocity="30.1" />
  </joint>
  <link name="RR_hip_rotor">
    <inertial>
      <origin rpy="0 0 0" xyz="0.0 0.0 0.0" />
      <mass value="0.089" />
      <inertia ixx="0.000111842" ixy="0.0" ixz="0.0" iyy="0.000059647" iyz="0.0" izz="0.000059647" />
    </inertial>
  </link>
  <joint name="RR_hip_rotor_joint" type="fixed">
    <origin rpy="0 0 0" xyz="-0.11215 -0.04675 0" />
    <parent link="base" />
    <child link="RR_hip_rotor" />
  </joint>
  <link name="RR_thigh">
    <inertial>
      <origin xyz="-0.00374 0.0223 -0.0327" rpy="0 0 0" />
      <mass value="1.152" />
      <inertia ixx="0.00584" ixy="-8.72E-05" ixz="-0.000289" iyy="0.0058" iyz="-0.000808" izz="0.00103" />
    </inertial>
    <visual>
      <origin xyz="0 0 0" rpy="0 0 0" />
      <geometry>
        <mesh filename="./meshes/thigh_mirror.dae" />
      </geometry>
      <material name="深色橡胶_012-effect"><color rgba="0.6717055 0.6924257 0.7742702 1" /></material><material name="Material_011-effect"><color rgba="0.9 0.95 0.95 1" /></material></visual>
    <collision>
      <origin rpy="0 1.5707963267948966 0" xyz="0 0 -0.1065" />
      <geometry>
        <box size="0.213 0.0245 0.034" />
      </geometry>
    </collision>
  </link>
  <joint name="RR_thigh_joint" type="revolute">
    <origin xyz="0 -0.0955 0" rpy="0 0 0" />
    <parent link="RR_hip" />
    <child link="RR_thigh" />
    <axis xyz="0 1 0" />
    <limit lower="-0.5236" upper="4.5379" effort="23.7" velocity="30.1" />
  </joint>
  <link name="RR_thigh_rotor">
    <inertial>
      <origin rpy="0 0 0" xyz="0.0 0.0 0.0" />
      <mass value="0.089" />
      <inertia ixx="0.000059647" ixy="0.0" ixz="0.0" iyy="0.000111842" iyz="0.0" izz="0.000059647" />
    </inertial>
  </link>
  <joint name="RR_thigh_rotor_joint" type="fixed">
    <origin rpy="0 0 0" xyz="0 0.00015 0" />
    <parent link="RR_hip" />
    <child link="RR_thigh_rotor" />
  </joint>
  <link name="RR_calf">
    <inertial>
      <origin xyz="0.00548 0.000975 -0.115" rpy="0 0 0" />
      <mass value="0.154" />
      <inertia ixx="0.00108" ixy="-3.4E-07" ixz="1.72E-05" iyy="0.0011" iyz="-8.28E-06" izz="3.29E-05" />
    </inertial>
    <visual>
      <origin xyz="0 0 0" rpy="0 0 0" />
      <geometry>
        <mesh filename="./meshes/calf_mirror.dae" />
      </geometry>
      <material name="黑色足端_006-effect"><color rgba="0 0 0 1" /></material><material name="深色橡胶_007-effect"><color rgba="0.6717055 0.6924257 0.7742702 1" /></material></visual>
    <collision>
      <origin rpy="0 -0.2 0" xyz="0.01 0 -0.06" />
      <geometry>
        <cylinder length="0.12" radius="0.013" />
      </geometry>
    </collision>
  </link>
  <joint name="RR_calf_joint" type="revolute">
    <origin xyz="0 0 -0.213" rpy="0 0 0" />
    <parent link="RR_thigh" />
    <child link="RR_calf" />
    <axis xyz="0 1 0" />
    <limit lower="-2.7227" upper="-0.83776" effort="45.43" velocity="15.70" />
  </joint>
  <link name="RR_calflower">
    <collision>
      <origin rpy="0 0 0" xyz="0 0 0" />
      <geometry>
        <cylinder length="0.065" radius="0.011" />
      </geometry>
    </collision>
  </link>
  <joint name="RR_calflower_joint" type="fixed">
    <origin xyz="0.020 0 -0.148" rpy="0 0.05 0" />
    <parent link="RR_calf" />
    <child link="RR_calflower" />
    <axis xyz="0 0 0" />
  </joint>
  <link name="RR_calflower1">
    <collision>
      <origin rpy="0 0 0" xyz="0 0 0" />
      <geometry>
        <cylinder length="0.03" radius="0.0155" />
      </geometry>
    </collision>
  </link>
  <joint name="RR_calflower1_joint" type="fixed">
    <origin xyz="-0.01 0 -0.04" rpy="0 0.48 0" />
    <parent link="RR_calflower" />
    <child link="RR_calflower1" />
    <axis xyz="0 0 0" />
  </joint>
  <link name="RR_calf_rotor">
    <inertial>
      <origin rpy="0 0 0" xyz="0.0 0.0 0.0" />
      <mass value="0.089" />
      <inertia ixx="0.000059647" ixy="0.0" ixz="0.0" iyy="0.000111842" iyz="0.0" izz="0.000059647" />
    </inertial>
  </link>
  <joint name="RR_calf_rotor_joint" type="fixed">
    <origin rpy="0 0 0" xyz="0 0.03235 0" />
    <parent link="RR_thigh" />
    <child link="RR_calf_rotor" />
  </joint>
  <link name="RR_foot">
    <inertial>
      <origin xyz="0 0 0" rpy="0 0 0" />
      <mass value="0.04" />
      <inertia ixx="9.6e-06" ixy="0" ixz="0" iyy="9.6e-06" iyz="0" izz="9.6e-06" />
    </inertial>
    <visual>
      <origin xyz="0 0 0" rpy="0 0 0" />
      <geometry>
        <mesh filename="./meshes/foot.dae" />
      </geometry>
      <material name="黑色足端_007-effect"><color rgba="0 0 0 1" /></material></visual>
    <collision>
      <origin rpy="0 0 0" xyz="-0.002 0 0" />
      <geometry>
        <sphere radius="0.022" />
      </geometry>
    </collision>
  </link>
  <joint name="RR_foot_joint" type="fixed" dont_collapse="true">
    <origin xyz="0 0 -0.213" rpy="0 0 0" />
    <parent link="RR_calf" />
    <child link="RR_foot" />
    <axis xyz="0 0 0" />
  </joint>
  <link name="imu">
    <inertial>
      <origin xyz="0 0 0" rpy="0 0 0" />
      <mass value="0" />
      <inertia ixx="0" ixy="0" ixz="0" iyy="0" iyz="0" izz="0" />
    </inertial>
  </link>
  <joint name="imu_joint" type="fixed">
    <origin xyz="-0.02557 0 0.04232" rpy="0 0 0" />
    <parent link="base" />
    <child link="imu" />
    <axis xyz="0 0 0" />
  </joint>
  <link name="radar">
    <inertial>
      <origin xyz="0 0 0" rpy="0 0 0" />
      <mass value="0" />
      <inertia ixx="0" ixy="0" ixz="0" iyy="0" iyz="0" izz="0" />
    </inertial>
  </link>
  <joint name="radar_joint" type="fixed">
    <origin xyz="0.28945 0 -0.046825" rpy="0 2.8782 0" />
    <parent link="base" />
    <child link="radar" />
    <axis xyz="0 0 0" />
  </joint>
  <joint name="front_camera_joint" type="fixed">
    <origin rpy="0 0 0" xyz="0.32715 -0.00003 0.04297" />
      <parent link="base" />
      <child link="front_camera" />
  </joint>
  <link name="front_camera">
  </link>

  <!-- X5 Arm attached to GO2 back -->
  <!-- Connection joint between GO2 base and X5 arm base -->
  <joint name="arm_base_joint" type="fixed">
    <origin xyz="0.12 0 0.05" rpy="0 0 0"/>
    <parent link="base"/>
    <child link="arm_base_link"/>
  </joint>

  <!-- X5A Arm Robot (with parallel gripper) -->
  <link name="arm_base_link">
    <inertial>
      <origin xyz="-3.0001e-05 3.0589e-05 0.027324" rpy="0 0 0"/>
      <mass value="0.43995"/>
      <inertia ixx="0.00017" ixy="0.00000" ixz="0.00000" iyy="0.00017" iyz="0.00000" izz="0.00016"/>
    </inertial>
    <visual>
      <origin xyz="0 0 0" rpy="0 0 0"/>
      <geometry>
        <mesh filename="./meshes/X5/base_link.STL"/>
      </geometry>
      <material name="">
        <color rgba="0.75294 0.75294 0.75294 1"/>
      </material>
    </visual>
    <collision>
      <origin xyz="0 0 0" rpy="0 0 0"/>
      <geometry>
        <mesh filename="./meshes/X5/base_link.STL"/>
      </geometry>
    </collision>
  </link>
  <link name="arm_link1">
    <inertial>
      <origin xyz="0.0054231 -0.0080289 0.017086" rpy="0 0 0"/>
      <mass value="0.066982"/>
      <inertia ixx="0.00008" ixy="0.00000" ixz="0.00001" iyy="0.00003" iyz="0.00000" izz="0.00008"/>
    </inertial>
    <visual>
      <origin xyz="0 0 0" rpy="0 0 0"/>
      <geometry>
        <mesh filename="./meshes/X5/link1.STL"/>
      </geometry>
      <material name="">
        <color rgba="0.79216 0.81961 0.93333 1"/>
      </material>
    </visual>
    <collision>
      <origin xyz="0 0 0" rpy="0 0 0"/>
      <geometry>
        <mesh filename="./meshes/X5/link1.STL"/>
      </geometry>
    </collision>
  </link>
  <joint name="arm_joint1" type="revolute">
    <origin xyz="0 0 0.0605" rpy="0 0 0"/>
    <parent link="arm_base_link"/>
    <child link="arm_link1"/>
    <axis xyz="0 0 1"/>
    <limit lower="-2.618" upper="3.14" effort="15" velocity="3"/>
    <dynamics damping="0.5" friction="0.1"/>
  </joint>
  <link name="arm_link2">
    <inertial>
      <origin xyz="-0.13237 0.0020852 0.00010549" rpy="0 0 0"/>
      <mass value="1.0795"/>
      <inertia ixx="0.00051" ixy="0.00001" ixz="-0.00004" iyy="0.01599" iyz="0.00000" izz="0.01605"/>
    </inertial>
    <visual>
      <origin xyz="0 0 0" rpy="0 0 0"/>
      <geometry>
        <mesh filename="./meshes/X5/link2.STL"/>
      </geometry>
      <material name="">
        <color rgba="0.75294 0.75294 0.75294 1"/>
      </material>
    </visual>
    <collision>
      <origin xyz="0 0 0" rpy="0 0 0"/>
      <geometry>
        <mesh filename="./meshes/X5/link2.STL"/>
      </geometry>
    </collision>
  </link>
  <joint name="arm_joint2" type="revolute">
    <origin xyz="0.02 0 0.04" rpy="0 0 0"/>
    <parent link="arm_link1"/>
    <child link="arm_link2"/>
    <axis xyz="0 1 0"/>
    <limit lower="0" upper="3.14" effort="15" velocity="3"/>
    <dynamics damping="0.5" friction="0.1"/>
  </joint>
  <link name="arm_link3">
    <inertial>
      <origin xyz="0.18531 0.00068376 -0.051638" rpy="0 0 0"/>
      <mass value="0.54534"/>
      <inertia ixx="0.00036" ixy="-0.00003" ixz="-0.00039" iyy="0.00423" iyz="0.00001" izz="0.00420"/>
    </inertial>
    <visual>
      <origin xyz="0 0 0" rpy="0 0 0"/>
      <geometry>
        <mesh filename="./meshes/X5/link3.STL"/>
      </geometry>
      <material name="">
        <color rgba="1 0.98431 0.96471 1"/>
      </material>
    </visual>
    <collision>
      <origin xyz="0 0 0" rpy="0 0 0"/>
      <geometry>
        <mesh filename="./meshes/X5/link3.STL"/>
      </geometry>
    </collision>
  </link>
  <joint name="arm_joint3" type="revolute">
    <origin xyz="-0.264 0 0" rpy="3.1416 0 0"/>
    <parent link="arm_link2"/>
    <child link="arm_link3"/>
    <axis xyz="0 1 0"/>
    <limit lower="0" upper="3.14" effort="15" velocity="3"/>
    <dynamics damping="0.5" friction="0.1"/>
  </joint>
  <link name="arm_link4">
    <inertial>
      <origin xyz="0.040231 0.0044807 -0.035335" rpy="0 0 0"/>
      <mass value="0.11714"/>
      <inertia ixx="0.00019" ixy="-0.00002" ixz="-0.00009" iyy="0.00023" iyz="0.00002" izz="0.00014"/>
    </inertial>
    <visual>
      <origin xyz="0 0 0" rpy="0 0 0"/>
      <geometry>
        <mesh filename="./meshes/X5/link4.STL"/>
      </geometry>
      <material name="">
        <color rgba="0.79216 0.81961 0.93333 1"/>
      </material>
    </visual>
    <collision>
      <origin xyz="0 0 0" rpy="0 0 0"/>
      <geometry>
        <mesh filename="./meshes/X5/link4.STL"/>
      </geometry>
    </collision>
  </link>
  <joint name="arm_joint4" type="revolute">
    <origin xyz="0.245 0 -0.056" rpy="0 0 0"/>
    <parent link="arm_link3"/>
    <child link="arm_link4"/>
    <axis xyz="0 1 0"/>
    <limit lower="-1.5708" upper="1.5708" effort="3" velocity="3"/>
    <dynamics damping="0.3" friction="0.1"/>
  </joint>
  <link name="arm_link5">
    <inertial>
      <origin xyz="0.003612 -1.5455e-05 0.055214" rpy="0 0 0"/>
      <mass value="0.63488"/>
      <inertia ixx="0.00083" ixy="0.00000" ixz="0.00007" iyy="0.00082" iyz="0.00000" izz="0.00026"/>
    </inertial>
    <visual>
      <origin xyz="0 0 0" rpy="0 0 0"/>
      <geometry>
        <mesh filename="./meshes/X5/link5.STL"/>
      </geometry>
      <material name="">
        <color rgba="0.69804 0.69804 0.69804 1"/>
      </material>
    </visual>
    <collision>
      <origin xyz="0 0 0" rpy="0 0 0"/>
      <geometry>
        <mesh filename="./meshes/X5/link5.STL"/>
      </geometry>
    </collision>
  </link>
  <joint name="arm_joint5" type="revolute">
    <origin xyz="0.06775 0.0005 -0.0865" rpy="0 0 0"/>
    <parent link="arm_link4"/>
    <child link="arm_link5"/>
    <axis xyz="0 0 1"/>
    <limit lower="-1.5708" upper="1.5708" effort="3" velocity="3"/>
    <dynamics damping="0.3" friction="0.1"/>
  </joint>
  <link name="arm_link6">
    <inertial>
      <origin xyz="0.041697 2.4368e-05 0.00014464" rpy="0 0 0"/>
      <mass value="0.44089"/>
      <inertia ixx="0.00038" ixy="0.00000" ixz="0.00000" iyy="0.00028" iyz="0.00000" izz="0.00050"/>
    </inertial>
    <visual>
      <origin xyz="0 0 0" rpy="0 0 0"/>
      <geometry>
        <mesh filename="./meshes/X5/link6.STL"/>
      </geometry>
      <material name="">
        <color rgba="0.89804 0.91765 0.92941 1"/>
      </material>
    </visual>
    <collision>
      <origin xyz="0 0 0" rpy="0 0 0"/>
      <geometry>
        <mesh filename="./meshes/X5/link6.STL"/>
      </geometry>
    </collision>
  </link>
  <joint name="arm_joint6" type="revolute">
    <origin xyz="0.02895 0 0.0865" rpy="-3.1416 0 0"/>
    <parent link="arm_link5"/>
    <child link="arm_link6"/>
    <axis xyz="1 0 0"/>
    <limit lower="-1.5708" upper="1.5708" effort="3" velocity="3"/>
    <dynamics damping="0.3" friction="0.1"/>
  </joint>

  <!-- Parallel Gripper -->
  <link name="arm_link7">
    <inertial>
      <origin xyz="-0.00035522 -0.007827 -0.0029883" rpy="0 0 0"/>
      <mass value="0.064798"/>
      <inertia ixx="0.00002" ixy="0.00000" ixz="0.00000" iyy="0.00003" iyz="0.00000" izz="0.00003"/>
    </inertial>
    <visual>
      <origin xyz="0 0 0" rpy="0 0 0"/>
      <geometry>
        <mesh filename="./meshes/X5/link7.STL"/>
      </geometry>
      <material name="">
        <color rgba="1 1 1 1"/>
      </material>
    </visual>
    <collision>
      <origin xyz="0 0 0" rpy="0 0 0"/>
      <geometry>
        <mesh filename="./meshes/X5/link7.STL"/>
      </geometry>
    </collision>
  </link>
  <joint name="arm_joint7" type="prismatic">
    <origin xyz="0.08657 0.024896 -0.0002436" rpy="0 0 0"/>
    <parent link="arm_link6"/>
    <child link="arm_link7"/>
    <axis xyz="0 1 0"/>
    <limit lower="0" upper="0.044" effort="20" velocity="1"/>
    <dynamics damping="0.1" friction="0.05"/>
  </joint>
  <link name="arm_link8">
    <inertial>
      <origin xyz="-0.00035522 0.0078277 0.0024201" rpy="0 0 0"/>
      <mass value="0.064798"/>
      <inertia ixx="0.00002" ixy="0.00000" ixz="0.00000" iyy="0.00003" iyz="0.00000" izz="0.00003"/>
    </inertial>
    <visual>
      <origin xyz="0 0 0" rpy="0 0 0"/>
      <geometry>
        <mesh filename="./meshes/X5/link8.STL"/>
      </geometry>
      <material name="">
        <color rgba="1 1 1 1"/>
      </material>
    </visual>
    <collision>
      <origin xyz="0 0 0" rpy="0 0 0"/>
      <geometry>
        <mesh filename="./meshes/X5/link8.STL"/>
      </geometry>
    </collision>
  </link>
  <joint name="arm_joint8" type="prismatic">
    <origin xyz="0.08657 -0.0249 -0.00024366" rpy="0 0 0"/>
    <parent link="arm_link6"/>
    <child link="arm_link8"/>
    <axis xyz="0 -1 0"/>
    <limit lower="0" upper="0.044" effort="20" velocity="1"/>
    <dynamics damping="0.1" friction="0.05"/>
    <mimic joint="arm_joint7" multiplier="1" offset="0"/>
  </joint>

  <!-- End-effector frame (centered between gripper fingers) -->
  <link name="arm_eef_link">
    <inertial>
      <mass value="0.0"/>
      <origin xyz="0.0 0.0 0.0" rpy="0 0 0"/>
      <inertia ixx="0.0" ixy="0.0" ixz="0.0" iyy="0.0" iyz="0.0" izz="0.0"/>
    </inertial>
  </link>
  <joint name="arm_gripper_fixed_joint" type="fixed">
    <origin xyz="0.08657 0.0 0.0" rpy="0 0 0"/>
    <parent link="arm_link6"/>
    <child link="arm_eef_link"/>
  </joint>

</robot>